<?xml version="1.0" ?>
<sdf version="1.9">
  <model name="simple_robot" canonical_link='chassis'>
    <pose>0 0 0 0 0 0</pose>

    <!-- ====================== CHASSIS ====================== -->
    <link name='chassis'>
      <pose relative_to='__model__'>0.05 0 0.04 0 0 0</pose>
      <inertial>
        <mass>1</mass>
        <inertia>
          <ixx>0.001191615</ixx>
          <ixy>0</ixy>
          <ixz>0</ixz>
          <iyy>0.004051490</iyy>
          <iyz>0</iyz>
          <izz>0.004766458</izz>
        </inertia>
      </inertial>
      <visual name='visual'>
        <geometry>
          <box>
            <size>0.2 0.1 0.05</size>
          </box>
        </geometry>
        <material>
          <ambient>0.0 0.612 0.867 1</ambient>
          <diffuse>0.0 0.612 0.867 1</diffuse>
          <specular>0.0 0.612 0.867 1</specular>
        </material>
      </visual>
      <collision name='collision'>
        <geometry>
          <box>
            <size>0.2 0.1 0.05</size>
          </box>
        </geometry>
      </collision>
    </link>

    <!-- ====================== LEFT WHEEL ====================== -->
    <link name='left_wheel'>
      <pose relative_to="chassis">-0.05 0.06 0 -1.5707 0 0</pose>
      <inertial>
        <mass>0.2</mass>
        <inertia>
          <ixx>0.000800</ixx>
          <ixy>0</ixy>
          <ixz>0</ixz>
          <iyy>0.000433</iyy>
          <iyz>0</iyz>
          <izz>0.000433</izz>
        </inertia>
      </inertial>
      <visual name='visual'>
        <geometry>
          <cylinder>
            <radius>0.04</radius>
            <length>0.02</length>
          </cylinder>
        </geometry>
        <material>
          <ambient>0.0 0.29 0.46 1</ambient>
          <diffuse>0.0 0.29 0.46 1</diffuse>
          <specular>0.0 0.0 0.0 1</specular>
        </material>
      </visual>
      <collision name='collision'>
        <geometry>
          <cylinder>
            <radius>0.04</radius>
            <length>0.02</length>
          </cylinder>
        </geometry>
      </collision>
    </link>

    <!-- ====================== RIGHT WHEEL ====================== -->
    <link name='right_wheel'>
      <pose relative_to="chassis">-0.05 -0.06 0 -1.5707 0 0</pose>
      <inertial>
        <mass>0.2</mass>
        <inertia>
          <ixx>0.000800</ixx>
          <ixy>0</ixy>
          <ixz>0</ixz>
          <iyy>0.000433</iyy>
          <iyz>0</iyz>
          <izz>0.000433</izz>
        </inertia>
      </inertial>
      <visual name='visual'>
        <geometry>
          <cylinder>
            <radius>0.04</radius>
            <length>0.02</length>
          </cylinder>
        </geometry>
        <material>
          <ambient>0.0 0.29 0.46 1</ambient>
          <diffuse>0.0 0.29 0.46 1</diffuse>
          <specular>0.0 0.0 0.0 1</specular>
        </material>
      </visual>
      <collision name='collision'>
        <geometry>
          <cylinder>
            <radius>0.04</radius>
            <length>0.02</length>
          </cylinder>
        </geometry>
      </collision>
    </link>

    <!-- ====================== CASTER WHEEL ====================== -->
    <frame name="caster_frame" attached_to='chassis'>
      <pose>0.08 0 -0.02 0 0 0</pose>
    </frame>

    <link name='caster'>
      <pose relative_to='caster_frame'/>
      <inertial>
        <mass>0.1</mass>
        <inertia>
          <ixx>0.00016</ixx>
          <ixy>0</ixy>
          <ixz>0</ixz>
          <iyy>0.00016</iyy>
          <iyz>0</iyz>
          <izz>0.00016</izz>
        </inertia>
      </inertial>
      <visual name='visual'>
        <geometry><sphere><radius>0.02</radius></sphere></geometry>
        <material>
          <ambient>0.0 0.29 0.46 1</ambient>
          <diffuse>0.0 0.29 0.46 1</diffuse>
        </material>
      </visual>
      <collision name='collision'>
        <geometry><sphere><radius>0.02</radius></sphere></geometry>
      </collision>
    </link>

    <!-- ====================== CAMERA LINK ====================== -->
    <link name="camera_link">
      <pose relative_to="chassis">0.1 0 0.08 0 0 0</pose>
      <inertial>
        <mass>0.01</mass>
        <inertia>
          <ixx>1e-6</ixx><iyy>1e-6</iyy><izz>1e-6</izz>
          <ixy>0</ixy><ixz>0</ixz><iyz>0</iyz>
        </inertia>
      </inertial>

      <!-- Camera visual (optional) -->
      <visual name="camera_visual">
        <geometry><box><size>0.03 0.03 0.03</size></box></geometry>
        <material>
          <ambient>0 0 0 1</ambient>
          <diffuse>0.2 0.2 0.2 1</diffuse>
        </material>
      </visual>

      <!-- Camera sensor -->
      <sensor name="camera_sensor" type="camera">
        <always_on>true</always_on>
        <update_rate>30</update_rate>
        <visualize>true</visualize>
        <camera>
          <horizontal_fov>1.047</horizontal_fov>
          <image><width>640</width><height>480</height><format>R8G8B8</format></image>
          <clip><near>0.1</near><far>100</far></clip>
        </camera>
        <topic>camera/image_raw</topic>
      </sensor>
    </link>

    <!-- ====================== JOINTS ====================== -->
    <joint name='left_wheel_joint' type='revolute'>
      <pose relative_to='left_wheel'/>
      <parent>chassis</parent>
      <child>left_wheel</child>
      <axis><xyz expressed_in='__model__'>0 1 0</xyz></axis>
    </joint>

    <joint name='right_wheel_joint' type='revolute'>
      <pose relative_to='right_wheel'/>
      <parent>chassis</parent>
      <child>right_wheel</child>
      <axis><xyz expressed_in='__model__'>0 1 0</xyz></axis>
    </joint>

    <joint name='caster_wheel' type='ball'>
      <parent>chassis</parent>
      <child>caster</child>
    </joint>

    <!-- Camera fixed joint -->
    <joint name="camera_joint" type="fixed">
      <parent>chassis</parent>
      <child>camera_link</child>
    </joint>

    <!-- ====================== DIFF DRIVE PLUGIN ====================== -->
    <plugin
      filename="libignition-gazebo-diff-drive-system.so"
      name="ignition::gazebo::systems::DiffDrive">
      <left_joint>left_wheel_joint</left_joint>
      <right_joint>right_wheel_joint</right_joint>
      <wheel_separation>0.12</wheel_separation>
      <wheel_radius>0.04</wheel_radius>
      <odom_publish_frequency>1</odom_publish_frequency>
      <topic>cmd_vel</topic>
    </plugin>

  </model>
</sdf>

